Workbook
Name MethodPointer1: -1271565216
Name MethodPointer2: 496

Sheet Plate 1 - Sheet1
A2: Software Version | B2: 3.14.03
A4: Experiment File Path: | B4: D:\GEAGS_Data\8.002R1.xpt
A5: Protocol File Path: | B5: C:\Users\Public\Documents\Protocols\CYH\YFP-COURSE.prt
A6: Plate Number | B6: Plate 1
A7: Date | B7: 43761
A8: Time | B8: 0.71563657
A9: Reader Type: | B9: Synergy H1
A10: Reader Serial Number: | B10: 268449
A11: Reading Type | B11: Reader
A13: Procedure Details
A14: Plate Type | B14: 96 WELL PLATE (Use plate lid)
A15: Eject plate on completion
A16: Set Temperature | B16: Setpoint 37°C
B17: Preheat before moving to next step
A18: Start Kinetic | B18: Runtime 12:00:00 (HH:MM:SS), Interval 0:10:00, 73 Reads
A19: Shake | B19: Linear: Continuous
B20: Frequency: 1096 cpm (1 mm)
A21: Read | B21: sfYFP
B22: Fluorescence Endpoint
B23: C1..D12
B24: Filter Set 1
B25: Excitation: 503, Emission: 540
B26: Optics: Bottom, Gain: 61
B27: Filter Set 2
B28: Excitation: 503, Emission: 540
B29: Optics: Bottom, Gain: 100
B30: Light Source: Xenon Flash, Lamp Energy: High
B31: Read Speed: Normal, Delay: 100 msec, Measurements/Data Point: 10
B32: Read Height: 7 mm
A33: Read | B33: OD600
B34: Absorbance Endpoint
B35: C1..D12
B36: Wavelengths: 600
B37: Read Speed: Normal, Delay: 100 msec, Measurements/Data Point: 8
A38: End Kinetic
A40: Layout
C42: 1 | D42: 2 | E42: 3 | F42: 4 | G42: 5 | H42: 6 | I42: 7 | J42: 8 | K42: 9 | L42: 10 | M42: 11 | N42: 12
B43: A | C43: SPL1 | D43: SPL9 | E43: SPL17 | F43: SPL25 | G43: SPL33 | H43: SPL41 | I43: SPL49 | J43: SPL57 | K43: SPL65 | L43: SPL73 | M43: SPL81 | N43: SPL89 | O43: Well ID
B44: B | C44: SPL2 | D44: SPL10 | E44: SPL18 | F44: SPL26 | G44: SPL34 | H44: SPL42 | I44: SPL50 | J44: SPL58 | K44: SPL66 | L44: SPL74 | M44: SPL82 | N44: SPL90 | O44: Well ID
B45: C | C45: SPL3 | D45: SPL11 | E45: SPL19 | F45: SPL27 | G45: SPL35 | H45: SPL43 | I45: SPL51 | J45: SPL59 | K45: SPL67 | L45: SPL75 | M45: SPL83 | N45: SPL91 | O45: Well ID
...

Sheet OD
A1: Time | B1: Time (min) | C1: C1 | D1: C2 | E1: C3 | F1: C4 | G1: C5 | H1: C6 | I1: C7 | J1: C8 | K1: C9 | L1: C10 | M1: C11 | N1: C12 | O1: D1 | P1: D2 | Q1: D3 | R1: D4 | S1: D5 | T1: D6 | U1: D7 | V1: D8 | W1: D9 | X1: D10 | Y1: D11 | Z1: D12
A2: 0.0067592593 | B2: 10 | C2: ='Plate 1 - Sheet1'!AB209 -> 0.08 | D2: ='Plate 1 - Sheet1'!AC209 -> 0.081 | E2: ='Plate 1 - Sheet1'!AD209 -> 0.083 | F2: ='Plate 1 - Sheet1'!AE209 -> 0.082 | G2: ='Plate 1 - Sheet1'!AF209 -> 0.084 | H2: ='Plate 1 - Sheet1'!AG209 -> 0.084 | I2: ='Plate 1 - Sheet1'!AH209 -> 0.084 | J2: ='Plate 1 - Sheet1'!AI209 -> 0.084 | ... Z2: ='Plate 1 - Sheet1'!AY209 -> 0.084
A3: 0.013703704 | B3: 20 | C3: ='Plate 1 - Sheet1'!AB210 -> 0.08 | D3: ='Plate 1 - Sheet1'!AC210 -> 0.081 | E3: ='Plate 1 - Sheet1'!AD210 -> 0.083 | F3: ='Plate 1 - Sheet1'!AE210 -> 0.082 | G3: ='Plate 1 - Sheet1'!AF210 -> 0.084 | H3: ='Plate 1 - Sheet1'!AG210 -> 0.084 | I3: ='Plate 1 - Sheet1'!AH210 -> 0.084 | J3: ='Plate 1 - Sheet1'!AI210 -> 0.084 | ... Z3: ='Plate 1 - Sheet1'!AY210 -> 0.084
A4: 0.020648148 | B4: 30 | C4: ='Plate 1 - Sheet1'!AB211 -> 0.08 | D4: ='Plate 1 - Sheet1'!AC211 -> 0.081 | E4: ='Plate 1 - Sheet1'!AD211 -> 0.083 | F4: ='Plate 1 - Sheet1'!AE211 -> 0.083 | G4: ='Plate 1 - Sheet1'!AF211 -> 0.084 | H4: ='Plate 1 - Sheet1'!AG211 -> 0.085 | I4: ='Plate 1 - Sheet1'!AH211 -> 0.084 | J4: ='Plate 1 - Sheet1'!AI211 -> 0.084 | ... Z4: ='Plate 1 - Sheet1'!AY211 -> 0.084
A5: 0.027592593 | B5: 40 | C5: ='Plate 1 - Sheet1'!AB212 -> 0.08 | D5: ='Plate 1 - Sheet1'!AC212 -> 0.08 | E5: ='Plate 1 - Sheet1'!AD212 -> 0.083 | F5: ='Plate 1 - Sheet1'!AE212 -> 0.083 | G5: ='Plate 1 - Sheet1'!AF212 -> 0.085 | H5: ='Plate 1 - Sheet1'!AG212 -> 0.085 | I5: ='Plate 1 - Sheet1'!AH212 -> 0.085 | J5: ='Plate 1 - Sheet1'!AI212 -> 0.084 | ... Z5: ='Plate 1 - Sheet1'!AY212 -> 0.085
A6: 0.034537037 | B6: 50 | C6: ='Plate 1 - Sheet1'!AB213 -> 0.08 | D6: ='Plate 1 - Sheet1'!AC213 -> 0.081 | E6: ='Plate 1 - Sheet1'!AD213 -> 0.083 | F6: ='Plate 1 - Sheet1'!AE213 -> 0.084 | G6: ='Plate 1 - Sheet1'!AF213 -> 0.085 | H6: ='Plate 1 - Sheet1'!AG213 -> 0.085 | I6: ='Plate 1 - Sheet1'!AH213 -> 0.085 | J6: ='Plate 1 - Sheet1'!AI213 -> 0.085 | ... Z6: ='Plate 1 - Sheet1'!AY213 -> 0.086
A7: 0.041481481 | B7: 60 | C7: ='Plate 1 - Sheet1'!AB214 -> 0.08 | D7: ='Plate 1 - Sheet1'!AC214 -> 0.08 | E7: ='Plate 1 - Sheet1'!AD214 -> 0.083 | F7: ='Plate 1 - Sheet1'!AE214 -> 0.084 | G7: ='Plate 1 - Sheet1'!AF214 -> 0.086 | H7: ='Plate 1 - Sheet1'!AG214 -> 0.085 | I7: ='Plate 1 - Sheet1'!AH214 -> 0.085 | J7: ='Plate 1 - Sheet1'!AI214 -> 0.085 | ... Z7: ='Plate 1 - Sheet1'!AY214 -> 0.09
A8: 0.048425926 | B8: 70 | C8: ='Plate 1 - Sheet1'!AB215 -> 0.08 | D8: ='Plate 1 - Sheet1'!AC215 -> 0.08 | E8: ='Plate 1 - Sheet1'!AD215 -> 0.083 | F8: ='Plate 1 - Sheet1'!AE215 -> 0.084 | G8: ='Plate 1 - Sheet1'!AF215 -> 0.086 | H8: ='Plate 1 - Sheet1'!AG215 -> 0.085 | I8: ='Plate 1 - Sheet1'!AH215 -> 0.085 | J8: ='Plate 1 - Sheet1'!AI215 -> 0.085 | ... Z8: ='Plate 1 - Sheet1'!AY215 -> 0.092
A9: 0.05537037 | B9: 80 | C9: ='Plate 1 - Sheet1'!AB216 -> 0.08 | D9: ='Plate 1 - Sheet1'!AC216 -> 0.081 | E9: ='Plate 1 - Sheet1'!AD216 -> 0.083 | F9: ='Plate 1 - Sheet1'!AE216 -> 0.084 | G9: ='Plate 1 - Sheet1'!AF216 -> 0.086 | H9: ='Plate 1 - Sheet1'!AG216 -> 0.085 | I9: ='Plate 1 - Sheet1'!AH216 -> 0.085 | J9: ='Plate 1 - Sheet1'!AI216 -> 0.085 | ... Z9: ='Plate 1 - Sheet1'!AY216 -> 0.095
A10: 0.062314815 | B10: 90 | C10: ='Plate 1 - Sheet1'!AB217 -> 0.08 | D10: ='Plate 1 - Sheet1'!AC217 -> 0.08 | E10: ='Plate 1 - Sheet1'!AD217 -> 0.083 | F10: ='Plate 1 - Sheet1'!AE217 -> 0.085 | G10: ='Plate 1 - Sheet1'!AF217 -> 0.086 | H10: ='Plate 1 - Sheet1'!AG217 -> 0.085 | I10: ='Plate 1 - Sheet1'!AH217 -> 0.085 | J10: ='Plate 1 - Sheet1'!AI217 -> 0.085 | ... Z10: ='Plate 1 - Sheet1'!AY217 -> 0.099
A11: 0.069259259 | B11: 100 | C11: ='Plate 1 - Sheet1'!AB218 -> 0.079 | D11: ='Plate 1 - Sheet1'!AC218 -> 0.08 | E11: ='Plate 1 - Sheet1'!AD218 -> 0.083 | F11: ='Plate 1 - Sheet1'!AE218 -> 0.085 | G11: ='Plate 1 - Sheet1'!AF218 -> 0.086 | H11: ='Plate 1 - Sheet1'!AG218 -> 0.085 | I11: ='Plate 1 - Sheet1'!AH218 -> 0.085 | J11: ='Plate 1 - Sheet1'!AI218 -> 0.085 | ... Z11: ='Plate 1 - Sheet1'!AY218 -> 0.103
A12: 0.076203704 | B12: 110 | C12: ='Plate 1 - Sheet1'!AB219 -> 0.08 | D12: ='Plate 1 - Sheet1'!AC219 -> 0.08 | E12: ='Plate 1 - Sheet1'!AD219 -> 0.083 | F12: ='Plate 1 - Sheet1'!AE219 -> 0.085 | G12: ='Plate 1 - Sheet1'!AF219 -> 0.086 | H12: ='Plate 1 - Sheet1'!AG219 -> 0.085 | I12: ='Plate 1 - Sheet1'!AH219 -> 0.085 | J12: ='Plate 1 - Sheet1'!AI219 -> 0.085 | ... Z12: ='Plate 1 - Sheet1'!AY219 -> 0.104
A13: 0.083148148 | B13: 120 | C13: ='Plate 1 - Sheet1'!AB220 -> 0.079 | D13: ='Plate 1 - Sheet1'!AC220 -> 0.08 | E13: ='Plate 1 - Sheet1'!AD220 -> 0.083 | F13: ='Plate 1 - Sheet1'!AE220 -> 0.085 | G13: ='Plate 1 - Sheet1'!AF220 -> 0.086 | H13: ='Plate 1 - Sheet1'!AG220 -> 0.085 | I13: ='Plate 1 - Sheet1'!AH220 -> 0.085 | J13: ='Plate 1 - Sheet1'!AI220 -> 0.085 | ... Z13: ='Plate 1 - Sheet1'!AY220 -> 0.106
... A74: 0.50675926 | B74: 730 | C74: ='Plate 1 - Sheet1'!AB281 -> 0.08 | D74: ='Plate 1 - Sheet1'!AC281 -> 0.081 | E74: ='Plate 1 - Sheet1'!AD281 -> 0.083 | F74: ='Plate 1 - Sheet1'!AE281 -> 0.087 | G74: ='Plate 1 - Sheet1'!AF281 -> 0.087 | H74: ='Plate 1 - Sheet1'!AG281 -> 0.086 | I74: ='Plate 1 - Sheet1'!AH281 -> 0.085 | J74: ='Plate 1 - Sheet1'!AI281 -> 0.085 | ... Z74: ='Plate 1 - Sheet1'!AY281 -> 0.242

Sheet FL
B1: Time (min) | C1: C1 | D1: C2 | E1: C3 | F1: C4 | G1: C5 | H1: C6 | I1: C7 | J1: C8 | K1: C9 | L1: C10 | M1: C11 | N1: C12 | O1: D1 | P1: D2 | Q1: D3 | R1: D4 | S1: D5 | T1: D6 | U1: D7 | V1: D8 | W1: D9 | X1: D10 | Y1: D11 | Z1: D12
B2: 10 | C2: ='Plate 1 - Sheet1'!AB132 -> 30 | D2: ='Plate 1 - Sheet1'!AC132 -> 30 | E2: ='Plate 1 - Sheet1'!AD132 -> 26 | F2: ='Plate 1 - Sheet1'!AE132 -> 16 | G2: ='Plate 1 - Sheet1'!AF132 -> 7 | H2: ='Plate 1 - Sheet1'!AG132 -> 11 | I2: ='Plate 1 - Sheet1'!AH132 -> 17 | J2: ='Plate 1 - Sheet1'!AI132 -> 14 | ... Z2: ='Plate 1 - Sheet1'!AY132 -> 45
B3: 20 | C3: ='Plate 1 - Sheet1'!AB133 -> 30 | D3: ='Plate 1 - Sheet1'!AC133 -> 34 | E3: ='Plate 1 - Sheet1'!AD133 -> 35 | F3: ='Plate 1 - Sheet1'!AE133 -> 7 | G3: ='Plate 1 - Sheet1'!AF133 -> 13 | H3: ='Plate 1 - Sheet1'!AG133 -> 8 | I3: ='Plate 1 - Sheet1'!AH133 -> 13 | J3: ='Plate 1 - Sheet1'!AI133 -> 5 | ... Z3: ='Plate 1 - Sheet1'!AY133 -> 70
B4: 30 | C4: ='Plate 1 - Sheet1'!AB134 -> 44 | D4: ='Plate 1 - Sheet1'!AC134 -> 27 | E4: ='Plate 1 - Sheet1'!AD134 -> 26 | F4: ='Plate 1 - Sheet1'!AE134 -> 17 | G4: ='Plate 1 - Sheet1'!AF134 -> 10 | H4: ='Plate 1 - Sheet1'!AG134 -> 7 | I4: ='Plate 1 - Sheet1'!AH134 -> 4 | J4: ='Plate 1 - Sheet1'!AI134 -> 8 | ... Z4: ='Plate 1 - Sheet1'!AY134 -> 61
B5: 40 | C5: ='Plate 1 - Sheet1'!AB135 -> 21 | D5: ='Plate 1 - Sheet1'!AC135 -> 31 | E5: ='Plate 1 - Sheet1'!AD135 -> 38 | F5: ='Plate 1 - Sheet1'!AE135 -> 20 | G5: ='Plate 1 - Sheet1'!AF135 -> 7 | H5: ='Plate 1 - Sheet1'!AG135 -> 8 | I5: ='Plate 1 - Sheet1'!AH135 -> 21 | J5: ='Plate 1 - Sheet1'!AI135 -> 5 | ... Z5: ='Plate 1 - Sheet1'!AY135 -> 60
B6: 50 | C6: ='Plate 1 - Sheet1'!AB136 -> 25 | D6: ='Plate 1 - Sheet1'!AC136 -> 15 | E6: ='Plate 1 - Sheet1'!AD136 -> 29 | F6: ='Plate 1 - Sheet1'!AE136 -> 12 | G6: ='Plate 1 - Sheet1'!AF136 -> 14 | H6: ='Plate 1 - Sheet1'!AG136 -> 13 | I6: ='Plate 1 - Sheet1'!AH136 -> 0 | J6: ='Plate 1 - Sheet1'!AI136 -> 33 | ... Z6: ='Plate 1 - Sheet1'!AY136 -> 73
B7: 60 | C7: ='Plate 1 - Sheet1'!AB137 -> 31 | D7: ='Plate 1 - Sheet1'!AC137 -> 39 | E7: ='Plate 1 - Sheet1'!AD137 -> 35 | F7: ='Plate 1 - Sheet1'!AE137 -> 25 | G7: ='Plate 1 - Sheet1'!AF137 -> 8 | H7: ='Plate 1 - Sheet1'!AG137 -> 3 | I7: ='Plate 1 - Sheet1'!AH137 -> 20 | J7: ='Plate 1 - Sheet1'!AI137 -> 15 | ... Z7: ='Plate 1 - Sheet1'!AY137 -> 70
B8: 70 | C8: ='Plate 1 - Sheet1'!AB138 -> 16 | D8: ='Plate 1 - Sheet1'!AC138 -> 21 | E8: ='Plate 1 - Sheet1'!AD138 -> 34 | F8: ='Plate 1 - Sheet1'!AE138 -> 13 | G8: ='Plate 1 - Sheet1'!AF138 -> 8 | H8: ='Plate 1 - Sheet1'!AG138 -> 16 | I8: ='Plate 1 - Sheet1'!AH138 -> 15 | J8: ='Plate 1 - Sheet1'!AI138 -> 19 | ... Z8: ='Plate 1 - Sheet1'!AY138 -> 65
B9: 80 | C9: ='Plate 1 - Sheet1'!AB139 -> 41 | D9: ='Plate 1 - Sheet1'!AC139 -> 17 | E9: ='Plate 1 - Sheet1'!AD139 -> 35 | F9: ='Plate 1 - Sheet1'!AE139 -> 4 | G9: ='Plate 1 - Sheet1'!AF139 -> 13 | H9: ='Plate 1 - Sheet1'!AG139 -> 12 | I9: ='Plate 1 - Sheet1'!AH139 -> 16 | J9: ='Plate 1 - Sheet1'!AI139 -> 3 | ... Z9: ='Plate 1 - Sheet1'!AY139 -> 53
B10: 90 | C10: ='Plate 1 - Sheet1'!AB140 -> 39 | D10: ='Plate 1 - Sheet1'!AC140 -> 18 | E10: ='Plate 1 - Sheet1'!AD140 -> 40 | F10: ='Plate 1 - Sheet1'!AE140 -> 23 | G10: ='Plate 1 - Sheet1'!AF140 -> 9 | H10: ='Plate 1 - Sheet1'!AG140 -> 12 | I10: ='Plate 1 - Sheet1'!AH140 -> 25 | J10: ='Plate 1 - Sheet1'!AI140 -> 3 | ... Z10: ='Plate 1 - Sheet1'!AY140 -> 68
B11: 100 | C11: ='Plate 1 - Sheet1'!AB141 -> 34 | D11: ='Plate 1 - Sheet1'!AC141 -> 30 | E11: ='Plate 1 - Sheet1'!AD141 -> 40 | F11: ='Plate 1 - Sheet1'!AE141 -> 0 | G11: ='Plate 1 - Sheet1'!AF141 -> 17 | H11: ='Plate 1 - Sheet1'!AG141 -> 8 | I11: ='Plate 1 - Sheet1'!AH141 -> 12 | J11: ='Plate 1 - Sheet1'!AI141 -> 6 | ... Z11: ='Plate 1 - Sheet1'!AY141 -> 154
B12: 110 | C12: ='Plate 1 - Sheet1'!AB142 -> 20 | D12: ='Plate 1 - Sheet1'!AC142 -> 22 | E12: ='Plate 1 - Sheet1'!AD142 -> 26 | F12: ='Plate 1 - Sheet1'!AE142 -> 14 | G12: ='Plate 1 - Sheet1'!AF142 -> 11 | H12: ='Plate 1 - Sheet1'!AG142 -> 12 | I12: ='Plate 1 - Sheet1'!AH142 -> 17 | J12: ='Plate 1 - Sheet1'!AI142 -> 23 | ... Z12: ='Plate 1 - Sheet1'!AY142 -> 149
B13: 120 | C13: ='Plate 1 - Sheet1'!AB143 -> 37 | D13: ='Plate 1 - Sheet1'!AC143 -> 26 | E13: ='Plate 1 - Sheet1'!AD143 -> 19 | F13: ='Plate 1 - Sheet1'!AE143 -> 15 | G13: ='Plate 1 - Sheet1'!AF143 -> 6 | H13: ='Plate 1 - Sheet1'!AG143 -> 26 | I13: ='Plate 1 - Sheet1'!AH143 -> 16 | J13: ='Plate 1 - Sheet1'!AI143 -> 12 | ... Z13: ='Plate 1 - Sheet1'!AY143 -> 172
... B74: 730 | C74: ='Plate 1 - Sheet1'!AB204 -> 28 | D74: ='Plate 1 - Sheet1'!AC204 -> 28 | E74: ='Plate 1 - Sheet1'!AD204 -> 20 | F74: ='Plate 1 - Sheet1'!AE204 -> 3 | G74: ='Plate 1 - Sheet1'!AF204 -> 24 | H74: ='Plate 1 - Sheet1'!AG204 -> 7 | I74: ='Plate 1 - Sheet1'!AH204 -> 6 | J74: ='Plate 1 - Sheet1'!AI204 -> 10 | ... Z74: ='Plate 1 - Sheet1'!AY204 -> 1078

Sheet FL by OD
B1: Time (min) | C1: C1 | D1: C2 | E1: C3 | F1: C4 | G1: C5 | H1: C6 | I1: C7 | J1: C8 | K1: C9 | L1: C10 | M1: C11 | N1: C12 | O1: D1 | P1: D2 | Q1: D3 | R1: D4 | S1: D5 | T1: D6 | U1: D7 | V1: D8 | W1: D9 | X1: D10 | Y1: D11 | Z1: D12
B2: 10 | C2: =FL!C2/OD!C2 -> 375 | D2: =FL!D2/OD!D2 -> 370.37037 | E2: =FL!E2/OD!E2 -> 313.25301 | F2: =FL!F2/OD!F2 -> 195.12195 | G2: =FL!G2/OD!G2 -> 83.333333 | H2: =FL!H2/OD!H2 -> 130.95238 | I2: =FL!I2/OD!I2 -> 202.38095 | J2: =FL!J2/OD!J2 -> 166.66667 | ... Z2: =FL!Z2/OD!Z2 -> 535.71429
B3: 20 | C3: =FL!C3/OD!C3 -> 375 | D3: =FL!D3/OD!D3 -> 419.75309 | E3: =FL!E3/OD!E3 -> 421.68675 | F3: =FL!F3/OD!F3 -> 85.365854 | G3: =FL!G3/OD!G3 -> 154.7619 | H3: =FL!H3/OD!H3 -> 95.238095 | I3: =FL!I3/OD!I3 -> 154.7619 | J3: =FL!J3/OD!J3 -> 59.52381 | ... Z3: =FL!Z3/OD!Z3 -> 833.33333
B4: 30 | C4: =FL!C4/OD!C4 -> 550 | D4: =FL!D4/OD!D4 -> 333.33333 | E4: =FL!E4/OD!E4 -> 313.25301 | F4: =FL!F4/OD!F4 -> 204.81928 | G4: =FL!G4/OD!G4 -> 119.04762 | H4: =FL!H4/OD!H4 -> 82.352941 | I4: =FL!I4/OD!I4 -> 47.619048 | J4: =FL!J4/OD!J4 -> 95.238095 | ... Z4: =FL!Z4/OD!Z4 -> 726.19048
B5: 40 | C5: =FL!C5/OD!C5 -> 262.5 | D5: =FL!D5/OD!D5 -> 387.5 | E5: =FL!E5/OD!E5 -> 457.83133 | F5: =FL!F5/OD!F5 -> 240.96386 | G5: =FL!G5/OD!G5 -> 82.352941 | H5: =FL!H5/OD!H5 -> 94.117647 | I5: =FL!I5/OD!I5 -> 247.05882 | J5: =FL!J5/OD!J5 -> 59.52381 | ... Z5: =FL!Z5/OD!Z5 -> 705.88235
B6: 50 | C6: =FL!C6/OD!C6 -> 312.5 | D6: =FL!D6/OD!D6 -> 185.18519 | E6: =FL!E6/OD!E6 -> 349.39759 | F6: =FL!F6/OD!F6 -> 142.85714 | G6: =FL!G6/OD!G6 -> 164.70588 | H6: =FL!H6/OD!H6 -> 152.94118 | I6: =FL!I6/OD!I6 -> 0 | J6: =FL!J6/OD!J6 -> 388.23529 | ... Z6: =FL!Z6/OD!Z6 -> 848.83721
B7: 60 | C7: =FL!C7/OD!C7 -> 387.5 | D7: =FL!D7/OD!D7 -> 487.5 | E7: =FL!E7/OD!E7 -> 421.68675 | F7: =FL!F7/OD!F7 -> 297.61905 | G7: =FL!G7/OD!G7 -> 93.023256 | H7: =FL!H7/OD!H7 -> 35.294118 | I7: =FL!I7/OD!I7 -> 235.29412 | J7: =FL!J7/OD!J7 -> 176.47059 | ... Z7: =FL!Z7/OD!Z7 -> 777.77778
B8: 70 | C8: =FL!C8/OD!C8 -> 200 | D8: =FL!D8/OD!D8 -> 262.5 | E8: =FL!E8/OD!E8 -> 409.63855 | F8: =FL!F8/OD!F8 -> 154.7619 | G8: =FL!G8/OD!G8 -> 93.023256 | H8: =FL!H8/OD!H8 -> 188.23529 | I8: =FL!I8/OD!I8 -> 176.47059 | J8: =FL!J8/OD!J8 -> 223.52941 | ... Z8: =FL!Z8/OD!Z8 -> 706.52174
B9: 80 | C9: =FL!C9/OD!C9 -> 512.5 | D9: =FL!D9/OD!D9 -> 209.87654 | E9: =FL!E9/OD!E9 -> 421.68675 | F9: =FL!F9/OD!F9 -> 47.619048 | G9: =FL!G9/OD!G9 -> 151.16279 | H9: =FL!H9/OD!H9 -> 141.17647 | I9: =FL!I9/OD!I9 -> 188.23529 | J9: =FL!J9/OD!J9 -> 35.294118 | ... Z9: =FL!Z9/OD!Z9 -> 557.89474
B10: 90 | C10: =FL!C10/OD!C10 -> 487.5 | D10: =FL!D10/OD!D10 -> 225 | E10: =FL!E10/OD!E10 -> 481.92771 | F10: =FL!F10/OD!F10 -> 270.58824 | G10: =FL!G10/OD!G10 -> 104.65116 | H10: =FL!H10/OD!H10 -> 141.17647 | I10: =FL!I10/OD!I10 -> 294.11765 | J10: =FL!J10/OD!J10 -> 35.294118 | ... Z10: =FL!Z10/OD!Z10 -> 686.86869
B11: 100 | C11: =FL!C11/OD!C11 -> 430.37975 | D11: =FL!D11/OD!D11 -> 375 | E11: =FL!E11/OD!E11 -> 481.92771 | F11: =FL!F11/OD!F11 -> 0 | G11: =FL!G11/OD!G11 -> 197.67442 | H11: =FL!H11/OD!H11 -> 94.117647 | I11: =FL!I11/OD!I11 -> 141.17647 | J11: =FL!J11/OD!J11 -> 70.588235 | ... Z11: =FL!Z11/OD!Z11 -> 1495.1456
B12: 110 | C12: =FL!C12/OD!C12 -> 250 | D12: =FL!D12/OD!D12 -> 275 | E12: =FL!E12/OD!E12 -> 313.25301 | F12: =FL!F12/OD!F12 -> 164.70588 | G12: =FL!G12/OD!G12 -> 127.90698 | H12: =FL!H12/OD!H12 -> 141.17647 | I12: =FL!I12/OD!I12 -> 200 | J12: =FL!J12/OD!J12 -> 270.58824 | ... Z12: =FL!Z12/OD!Z12 -> 1432.6923
B13: 120 | C13: =FL!C13/OD!C13 -> 468.35443 | D13: =FL!D13/OD!D13 -> 325 | E13: =FL!E13/OD!E13 -> 228.91566 | F13: =FL!F13/OD!F13 -> 176.47059 | G13: =FL!G13/OD!G13 -> 69.767442 | H13: =FL!H13/OD!H13 -> 305.88235 | I13: =FL!I13/OD!I13 -> 188.23529 | J13: =FL!J13/OD!J13 -> 141.17647 | ... Z13: =FL!Z13/OD!Z13 -> 1622.6415
... B74: 730 | C74: =FL!C74/OD!C74 -> 350 | D74: =FL!D74/OD!D74 -> 345.67901 | E74: =FL!E74/OD!E74 -> 240.96386 | F74: =FL!F74/OD!F74 -> 34.482759 | G74: =FL!G74/OD!G74 -> 275.86207 | H74: =FL!H74/OD!H74 -> 81.395349 | I74: =FL!I74/OD!I74 -> 70.588235 | J74: =FL!J74/OD!J74 -> 117.64706 | ... Z74: =FL!Z74/OD!Z74 -> 4454.5455

Sheet Data For figure
A1: Time (min) | B1: D1 | C1: D2 | D1: D3 | E1: D4
A2: 10 | B2: 1442.1053 | C2: 2054.9451 | D2: 1888.8889 | E2: 2771.0843
A3: 20 | B3: 1372.3404 | C3: 1978.2609 | D3: 2177.7778 | E3: 2678.5714
A4: 30 | B4: 1705.2632 | C4: 2225.8065 | D4: 2142.8571 | E4: 2858.8235
A5: 40 | B5: 1438.7755 | C5: 2094.7368 | D5: 2413.0435 | E5: 2639.5349
A6: 50 | B6: 1390 | C6: 2247.4227 | D6: 2021.0526 | E6: 3022.4719
A7: 60 | B7: 1461.5385 | C7: 2666.6667 | D7: 1979.3814 | E7: 3195.6522
A8: 70 | B8: 1588.785 | C8: 2446.6019 | D8: 2160 | E8: 3156.25
A9: 80 | B9: 1646.0177 | C9: 3364.486 | D9: 2854.3689 | E9: 3650
A10: 90 | B10: 2016.6667 | C10: 3375 | D10: 2675.9259 | E10: 4085.7143
A11: 100 | B11: 2587.3016 | C11: 4025.4237 | D11: 3614.0351 | E11: 5133.9286
A12: 110 | B12: 2856.0606 | C12: 5235.7724 | D12: 4487.395 | E12: 6159.6639
A13: 120 | B13: 3281.6901 | C13: 5633.5878 | D13: 5039.6825 | E13: 6724.4094
... A74: 730 | B74: 1425.5692 | C74: 3141.5771 | D74: 3167.87 | E74: 2983.5165
