Workbook
Name MethodPointer1: 1627929696
Name MethodPointer2: 582

Sheet Plate 1 - Sheet1
A2: Software Version | B2: 3.14.03
A4: Experiment File Path: | B4: D:\GEAGS_Data\8.004R1.xpt
A5: Protocol File Path: | B5: C:\Users\Public\Documents\Protocols\CYH\YFP-COURSE.prt
A6: Plate Number | B6: Plate 1
A7: Date | B7: 43772
A8: Time | B8: 0.7687963
A9: Reader Type: | B9: Synergy H1
A10: Reader Serial Number: | B10: 268449
A11: Reading Type | B11: Reader
A13: Procedure Details
A14: Plate Type | B14: 96 WELL PLATE (Use plate lid)
A15: Eject plate on completion
A16: Set Temperature | B16: Setpoint 37°C
B17: Preheat before moving to next step
A18: Start Kinetic | B18: Runtime 18:00:00 (HH:MM:SS), Interval 0:10:00, 109 Reads
A19: Shake | B19: Linear: Continuous
B20: Frequency: 1096 cpm (1 mm)
A21: Read | B21: sfYFP
B22: Fluorescence Endpoint
B23: G1..G12
B24: Filter Set 1
B25: Excitation: 503, Emission: 540
B26: Optics: Bottom, Gain: 61
B27: Filter Set 2
B28: Excitation: 503, Emission: 540
B29: Optics: Bottom, Gain: 100
B30: Light Source: Xenon Flash, Lamp Energy: High
B31: Read Speed: Normal, Delay: 100 msec, Measurements/Data Point: 10
B32: Read Height: 7 mm
A33: Read | B33: OD600
B34: Absorbance Endpoint
B35: G1..G12
B36: Wavelengths: 600
B37: Read Speed: Normal, Delay: 100 msec, Measurements/Data Point: 8
A38: End Kinetic
A40: Layout
C42: 1 | D42: 2 | E42: 3 | F42: 4 | G42: 5 | H42: 6 | I42: 7 | J42: 8 | K42: 9 | L42: 10 | M42: 11 | N42: 12
B43: A | C43: SPL1 | D43: SPL9 | E43: SPL17 | F43: SPL25 | G43: SPL33 | H43: SPL41 | I43: SPL49 | J43: SPL57 | K43: SPL65 | L43: SPL73 | M43: SPL81 | N43: SPL89 | O43: Well ID
B44: B | C44: SPL2 | D44: SPL10 | E44: SPL18 | F44: SPL26 | G44: SPL34 | H44: SPL42 | I44: SPL50 | J44: SPL58 | K44: SPL66 | L44: SPL74 | M44: SPL82 | N44: SPL90 | O44: Well ID
B45: C | C45: SPL3 | D45: SPL11 | E45: SPL19 | F45: SPL27 | G45: SPL35 | H45: SPL43 | I45: SPL51 | J45: SPL59 | K45: SPL67 | L45: SPL75 | M45: SPL83 | N45: SPL91 | O45: Well ID
...

Sheet OD
A1: Time | B1: Time (min) | C1: G1 | D1: G2 | E1: G3 | F1: G4 | G1: G5 | H1: G6 | I1: G7 | J1: G8 | K1: G9 | L1: G10 | M1: G11 | N1: G12
A2: 0.0066203704 | B2: 10 | C2: ='Plate 1 - Sheet1'!BX281 -> 0.086 | D2: ='Plate 1 - Sheet1'!BY281 -> 0.086 | E2: ='Plate 1 - Sheet1'!BZ281 -> 0.087 | F2: ='Plate 1 - Sheet1'!CA281 -> 0.084 | G2: ='Plate 1 - Sheet1'!CB281 -> 0.086 | H2: ='Plate 1 - Sheet1'!CC281 -> 0.084 | I2: ='Plate 1 - Sheet1'!CD281 -> 0.08 | J2: ='Plate 1 - Sheet1'!CE281 -> 0.081 | ... N2: ='Plate 1 - Sheet1'!CI281 -> 0.087
A3: 0.013564815 | B3: 20 | C3: ='Plate 1 - Sheet1'!BX282 -> 0.087 | D3: ='Plate 1 - Sheet1'!BY282 -> 0.086 | E3: ='Plate 1 - Sheet1'!BZ282 -> 0.087 | F3: ='Plate 1 - Sheet1'!CA282 -> 0.085 | G3: ='Plate 1 - Sheet1'!CB282 -> 0.086 | H3: ='Plate 1 - Sheet1'!CC282 -> 0.084 | I3: ='Plate 1 - Sheet1'!CD282 -> 0.08 | J3: ='Plate 1 - Sheet1'!CE282 -> 0.083 | ... N3: ='Plate 1 - Sheet1'!CI282 -> 0.087
A4: 0.020509259 | B4: 30 | C4: ='Plate 1 - Sheet1'!BX283 -> 0.089 | D4: ='Plate 1 - Sheet1'!BY283 -> 0.087 | E4: ='Plate 1 - Sheet1'!BZ283 -> 0.088 | F4: ='Plate 1 - Sheet1'!CA283 -> 0.085 | G4: ='Plate 1 - Sheet1'!CB283 -> 0.087 | H4: ='Plate 1 - Sheet1'!CC283 -> 0.085 | I4: ='Plate 1 - Sheet1'!CD283 -> 0.08 | J4: ='Plate 1 - Sheet1'!CE283 -> 0.082 | ... N4: ='Plate 1 - Sheet1'!CI283 -> 0.089
A5: 0.027453704 | B5: 40 | C5: ='Plate 1 - Sheet1'!BX284 -> 0.091 | D5: ='Plate 1 - Sheet1'!BY284 -> 0.089 | E5: ='Plate 1 - Sheet1'!BZ284 -> 0.09 | F5: ='Plate 1 - Sheet1'!CA284 -> 0.087 | G5: ='Plate 1 - Sheet1'!CB284 -> 0.088 | H5: ='Plate 1 - Sheet1'!CC284 -> 0.086 | I5: ='Plate 1 - Sheet1'!CD284 -> 0.08 | J5: ='Plate 1 - Sheet1'!CE284 -> 0.083 | ... N5: ='Plate 1 - Sheet1'!CI284 -> 0.091
A6: 0.034398148 | B6: 50 | C6: ='Plate 1 - Sheet1'!BX285 -> 0.093 | D6: ='Plate 1 - Sheet1'!BY285 -> 0.092 | E6: ='Plate 1 - Sheet1'!BZ285 -> 0.093 | F6: ='Plate 1 - Sheet1'!CA285 -> 0.089 | G6: ='Plate 1 - Sheet1'!CB285 -> 0.091 | H6: ='Plate 1 - Sheet1'!CC285 -> 0.088 | I6: ='Plate 1 - Sheet1'!CD285 -> 0.081 | J6: ='Plate 1 - Sheet1'!CE285 -> 0.084 | ... N6: ='Plate 1 - Sheet1'!CI285 -> 0.094
A7: 0.041342593 | B7: 60 | C7: ='Plate 1 - Sheet1'!BX286 -> 0.097 | D7: ='Plate 1 - Sheet1'!BY286 -> 0.096 | E7: ='Plate 1 - Sheet1'!BZ286 -> 0.097 | F7: ='Plate 1 - Sheet1'!CA286 -> 0.093 | G7: ='Plate 1 - Sheet1'!CB286 -> 0.094 | H7: ='Plate 1 - Sheet1'!CC286 -> 0.091 | I7: ='Plate 1 - Sheet1'!CD286 -> 0.082 | J7: ='Plate 1 - Sheet1'!CE286 -> 0.086 | ... N7: ='Plate 1 - Sheet1'!CI286 -> 0.098
A8: 0.048287037 | B8: 70 | C8: ='Plate 1 - Sheet1'!BX287 -> 0.102 | D8: ='Plate 1 - Sheet1'!BY287 -> 0.101 | E8: ='Plate 1 - Sheet1'!BZ287 -> 0.102 | F8: ='Plate 1 - Sheet1'!CA287 -> 0.098 | G8: ='Plate 1 - Sheet1'!CB287 -> 0.098 | H8: ='Plate 1 - Sheet1'!CC287 -> 0.096 | I8: ='Plate 1 - Sheet1'!CD287 -> 0.082 | J8: ='Plate 1 - Sheet1'!CE287 -> 0.09 | ... N8: ='Plate 1 - Sheet1'!CI287 -> 0.102
A9: 0.055231481 | B9: 80 | C9: ='Plate 1 - Sheet1'!BX288 -> 0.109 | D9: ='Plate 1 - Sheet1'!BY288 -> 0.108 | E9: ='Plate 1 - Sheet1'!BZ288 -> 0.11 | F9: ='Plate 1 - Sheet1'!CA288 -> 0.103 | G9: ='Plate 1 - Sheet1'!CB288 -> 0.103 | H9: ='Plate 1 - Sheet1'!CC288 -> 0.101 | I9: ='Plate 1 - Sheet1'!CD288 -> 0.083 | J9: ='Plate 1 - Sheet1'!CE288 -> 0.092 | ... N9: ='Plate 1 - Sheet1'!CI288 -> 0.109
A10: 0.062175926 | B10: 90 | C10: ='Plate 1 - Sheet1'!BX289 -> 0.115 | D10: ='Plate 1 - Sheet1'!BY289 -> 0.115 | E10: ='Plate 1 - Sheet1'!BZ289 -> 0.115 | F10: ='Plate 1 - Sheet1'!CA289 -> 0.109 | G10: ='Plate 1 - Sheet1'!CB289 -> 0.11 | H10: ='Plate 1 - Sheet1'!CC289 -> 0.105 | I10: ='Plate 1 - Sheet1'!CD289 -> 0.085 | J10: ='Plate 1 - Sheet1'!CE289 -> 0.095 | ... N10: ='Plate 1 - Sheet1'!CI289 -> 0.115
A11: 0.06912037 | B11: 100 | C11: ='Plate 1 - Sheet1'!BX290 -> 0.124 | D11: ='Plate 1 - Sheet1'!BY290 -> 0.121 | E11: ='Plate 1 - Sheet1'!BZ290 -> 0.124 | F11: ='Plate 1 - Sheet1'!CA290 -> 0.116 | G11: ='Plate 1 - Sheet1'!CB290 -> 0.117 | H11: ='Plate 1 - Sheet1'!CC290 -> 0.113 | I11: ='Plate 1 - Sheet1'!CD290 -> 0.087 | J11: ='Plate 1 - Sheet1'!CE290 -> 0.099 | ... N11: ='Plate 1 - Sheet1'!CI290 -> 0.121
A12: 0.076064815 | B12: 110 | C12: ='Plate 1 - Sheet1'!BX291 -> 0.133 | D12: ='Plate 1 - Sheet1'!BY291 -> 0.13 | E12: ='Plate 1 - Sheet1'!BZ291 -> 0.132 | F12: ='Plate 1 - Sheet1'!CA291 -> 0.121 | G12: ='Plate 1 - Sheet1'!CB291 -> 0.122 | H12: ='Plate 1 - Sheet1'!CC291 -> 0.119 | I12: ='Plate 1 - Sheet1'!CD291 -> 0.089 | J12: ='Plate 1 - Sheet1'!CE291 -> 0.103 | ... N12: ='Plate 1 - Sheet1'!CI291 -> 0.129
A13: 0.083009259 | B13: 120 | C13: ='Plate 1 - Sheet1'!BX292 -> 0.144 | D13: ='Plate 1 - Sheet1'!BY292 -> 0.142 | E13: ='Plate 1 - Sheet1'!BZ292 -> 0.143 | F13: ='Plate 1 - Sheet1'!CA292 -> 0.132 | G13: ='Plate 1 - Sheet1'!CB292 -> 0.132 | H13: ='Plate 1 - Sheet1'!CC292 -> 0.127 | I13: ='Plate 1 - Sheet1'!CD292 -> 0.091 | J13: ='Plate 1 - Sheet1'!CE292 -> 0.108 | ... N13: ='Plate 1 - Sheet1'!CI292 -> 0.141
... A110: 0.75662037 | B110: 1090 | C110: ='Plate 1 - Sheet1'!BX389 -> 0.537 | D110: ='Plate 1 - Sheet1'!BY389 -> 0.55 | E110: ='Plate 1 - Sheet1'!BZ389 -> 0.558 | F110: ='Plate 1 - Sheet1'!CA389 -> 0.516 | G110: ='Plate 1 - Sheet1'!CB389 -> 0.519 | H110: ='Plate 1 - Sheet1'!CC389 -> 0.512 | I110: ='Plate 1 - Sheet1'!CD389 -> 0.537 | J110: ='Plate 1 - Sheet1'!CE389 -> 0.545 | ... N110: ='Plate 1 - Sheet1'!CI389 -> 0.486

Sheet FL
A1: Time | B1: Time (min) | C1: G1 | D1: G2 | E1: G3 | F1: G4 | G1: G5 | H1: G6 | I1: G7 | J1: G8 | K1: G9 | L1: G10 | M1: G11 | N1: G12
A2: 0.0066203704 | B2: 10 | C2: ='Plate 1 - Sheet1'!BX168 -> 26 | D2: ='Plate 1 - Sheet1'!BY168 -> 39 | E2: ='Plate 1 - Sheet1'!BZ168 -> 36 | F2: ='Plate 1 - Sheet1'!CA168 -> 236 | G2: ='Plate 1 - Sheet1'!CB168 -> 172 | H2: ='Plate 1 - Sheet1'!CC168 -> 206 | I2: ='Plate 1 - Sheet1'!CD168 -> 155 | J2: ='Plate 1 - Sheet1'!CE168 -> 257 | ... N2: ='Plate 1 - Sheet1'!CI168 -> 39
A3: 0.013564815 | B3: 20 | C3: ='Plate 1 - Sheet1'!BX169 -> 31 | D3: ='Plate 1 - Sheet1'!BY169 -> 34 | E3: ='Plate 1 - Sheet1'!BZ169 -> 26 | F3: ='Plate 1 - Sheet1'!CA169 -> 253 | G3: ='Plate 1 - Sheet1'!CB169 -> 192 | H3: ='Plate 1 - Sheet1'!CC169 -> 216 | I3: ='Plate 1 - Sheet1'!CD169 -> 163 | J3: ='Plate 1 - Sheet1'!CE169 -> 338 | ... N3: ='Plate 1 - Sheet1'!CI169 -> 51
A4: 0.020509259 | B4: 30 | C4: ='Plate 1 - Sheet1'!BX170 -> 41 | D4: ='Plate 1 - Sheet1'!BY170 -> 40 | E4: ='Plate 1 - Sheet1'!BZ170 -> 38 | F4: ='Plate 1 - Sheet1'!CA170 -> 278 | G4: ='Plate 1 - Sheet1'!CB170 -> 225 | H4: ='Plate 1 - Sheet1'!CC170 -> 238 | I4: ='Plate 1 - Sheet1'!CD170 -> 177 | J4: ='Plate 1 - Sheet1'!CE170 -> 347 | ... N4: ='Plate 1 - Sheet1'!CI170 -> 30
A5: 0.027453704 | B5: 40 | C5: ='Plate 1 - Sheet1'!BX171 -> 35 | D5: ='Plate 1 - Sheet1'!BY171 -> 35 | E5: ='Plate 1 - Sheet1'!BZ171 -> 29 | F5: ='Plate 1 - Sheet1'!CA171 -> 261 | G5: ='Plate 1 - Sheet1'!CB171 -> 245 | H5: ='Plate 1 - Sheet1'!CC171 -> 250 | I5: ='Plate 1 - Sheet1'!CD171 -> 190 | J5: ='Plate 1 - Sheet1'!CE171 -> 358 | ... N5: ='Plate 1 - Sheet1'!CI171 -> 36
A6: 0.034398148 | B6: 50 | C6: ='Plate 1 - Sheet1'!BX172 -> 35 | D6: ='Plate 1 - Sheet1'!BY172 -> 45 | E6: ='Plate 1 - Sheet1'!BZ172 -> 34 | F6: ='Plate 1 - Sheet1'!CA172 -> 273 | G6: ='Plate 1 - Sheet1'!CB172 -> 231 | H6: ='Plate 1 - Sheet1'!CC172 -> 271 | I6: ='Plate 1 - Sheet1'!CD172 -> 175 | J6: ='Plate 1 - Sheet1'!CE172 -> 414 | ... N6: ='Plate 1 - Sheet1'!CI172 -> 31
A7: 0.041342593 | B7: 60 | C7: ='Plate 1 - Sheet1'!BX173 -> 34 | D7: ='Plate 1 - Sheet1'!BY173 -> 39 | E7: ='Plate 1 - Sheet1'!BZ173 -> 51 | F7: ='Plate 1 - Sheet1'!CA173 -> 279 | G7: ='Plate 1 - Sheet1'!CB173 -> 262 | H7: ='Plate 1 - Sheet1'!CC173 -> 233 | I7: ='Plate 1 - Sheet1'!CD173 -> 203 | J7: ='Plate 1 - Sheet1'!CE173 -> 432 | ... N7: ='Plate 1 - Sheet1'!CI173 -> 35
A8: 0.048287037 | B8: 70 | C8: ='Plate 1 - Sheet1'!BX174 -> 33 | D8: ='Plate 1 - Sheet1'!BY174 -> 38 | E8: ='Plate 1 - Sheet1'!BZ174 -> 20 | F8: ='Plate 1 - Sheet1'!CA174 -> 345 | G8: ='Plate 1 - Sheet1'!CB174 -> 300 | H8: ='Plate 1 - Sheet1'!CC174 -> 319 | I8: ='Plate 1 - Sheet1'!CD174 -> 226 | J8: ='Plate 1 - Sheet1'!CE174 -> 499 | ... N8: ='Plate 1 - Sheet1'!CI174 -> 37
A9: 0.055231481 | B9: 80 | C9: ='Plate 1 - Sheet1'!BX175 -> 38 | D9: ='Plate 1 - Sheet1'!BY175 -> 24 | E9: ='Plate 1 - Sheet1'!BZ175 -> 42 | F9: ='Plate 1 - Sheet1'!CA175 -> 430 | G9: ='Plate 1 - Sheet1'!CB175 -> 347 | H9: ='Plate 1 - Sheet1'!CC175 -> 388 | I9: ='Plate 1 - Sheet1'!CD175 -> 215 | J9: ='Plate 1 - Sheet1'!CE175 -> 543 | ... N9: ='Plate 1 - Sheet1'!CI175 -> 38
A10: 0.062175926 | B10: 90 | C10: ='Plate 1 - Sheet1'!BX176 -> 30 | D10: ='Plate 1 - Sheet1'!BY176 -> 35 | E10: ='Plate 1 - Sheet1'!BZ176 -> 24 | F10: ='Plate 1 - Sheet1'!CA176 -> 480 | G10: ='Plate 1 - Sheet1'!CB176 -> 431 | H10: ='Plate 1 - Sheet1'!CC176 -> 443 | I10: ='Plate 1 - Sheet1'!CD176 -> 285 | J10: ='Plate 1 - Sheet1'!CE176 -> 665 | ... N10: ='Plate 1 - Sheet1'!CI176 -> 47
A11: 0.06912037 | B11: 100 | C11: ='Plate 1 - Sheet1'!BX177 -> 37 | D11: ='Plate 1 - Sheet1'!BY177 -> 49 | E11: ='Plate 1 - Sheet1'!BZ177 -> 43 | F11: ='Plate 1 - Sheet1'!CA177 -> 609 | G11: ='Plate 1 - Sheet1'!CB177 -> 530 | H11: ='Plate 1 - Sheet1'!CC177 -> 540 | I11: ='Plate 1 - Sheet1'!CD177 -> 294 | J11: ='Plate 1 - Sheet1'!CE177 -> 742 | ... N11: ='Plate 1 - Sheet1'!CI177 -> 31
A12: 0.076064815 | B12: 110 | C12: ='Plate 1 - Sheet1'!BX178 -> 35 | D12: ='Plate 1 - Sheet1'!BY178 -> 50 | E12: ='Plate 1 - Sheet1'!BZ178 -> 37 | F12: ='Plate 1 - Sheet1'!CA178 -> 752 | G12: ='Plate 1 - Sheet1'!CB178 -> 685 | H12: ='Plate 1 - Sheet1'!CC178 -> 630 | I12: ='Plate 1 - Sheet1'!CD178 -> 338 | J12: ='Plate 1 - Sheet1'!CE178 -> 931 | ... N12: ='Plate 1 - Sheet1'!CI178 -> 46
A13: 0.083009259 | B13: 120 | C13: ='Plate 1 - Sheet1'!BX179 -> 35 | D13: ='Plate 1 - Sheet1'!BY179 -> 41 | E13: ='Plate 1 - Sheet1'!BZ179 -> 40 | F13: ='Plate 1 - Sheet1'!CA179 -> 838 | G13: ='Plate 1 - Sheet1'!CB179 -> 752 | H13: ='Plate 1 - Sheet1'!CC179 -> 771 | I13: ='Plate 1 - Sheet1'!CD179 -> 396 | J13: ='Plate 1 - Sheet1'!CE179 -> 1134 | ... N13: ='Plate 1 - Sheet1'!CI179 -> 50
... A110: 0.75662037 | B110: 1090 | C110: ='Plate 1 - Sheet1'!BX276 -> 482 | D110: ='Plate 1 - Sheet1'!BY276 -> 486 | E110: ='Plate 1 - Sheet1'!BZ276 -> 505 | F110: ='Plate 1 - Sheet1'!CA276 -> 1220 | G110: ='Plate 1 - Sheet1'!CB276 -> 1259 | H110: ='Plate 1 - Sheet1'!CC276 -> 1238 | I110: ='Plate 1 - Sheet1'!CD276 -> 52666 | J110: ='Plate 1 - Sheet1'!CE276 -> 43353 | ... N110: ='Plate 1 - Sheet1'!CI276 -> 434

Sheet FL by OD
A1: Time | B1: Time (min) | C1: G1 | D1: G2 | E1: G3 | F1: G4 | G1: G5 | H1: G6 | I1: G7 | J1: G8 | K1: G9 | L1: G10 | M1: G11 | N1: G12
A2: 0.0066203704 | B2: 10 | C2: =FL!C2/OD!C2 -> 302.32558 | D2: =FL!D2/OD!D2 -> 453.48837 | E2: =FL!E2/OD!E2 -> 413.7931 | F2: =FL!F2/OD!F2 -> 2809.5238 | G2: =FL!G2/OD!G2 -> 2000 | H2: =FL!H2/OD!H2 -> 2452.381 | I2: =FL!I2/OD!I2 -> 1937.5 | J2: =FL!J2/OD!J2 -> 3172.8395 | ... N2: =FL!N2/OD!N2 -> 448.27586
A3: 0.013564815 | B3: 20 | C3: =FL!C3/OD!C3 -> 356.32184 | D3: =FL!D3/OD!D3 -> 395.34884 | E3: =FL!E3/OD!E3 -> 298.85057 | F3: =FL!F3/OD!F3 -> 2976.4706 | G3: =FL!G3/OD!G3 -> 2232.5581 | H3: =FL!H3/OD!H3 -> 2571.4286 | I3: =FL!I3/OD!I3 -> 2037.5 | J3: =FL!J3/OD!J3 -> 4072.2892 | ... N3: =FL!N3/OD!N3 -> 586.2069
A4: 0.020509259 | B4: 30 | C4: =FL!C4/OD!C4 -> 460.67416 | D4: =FL!D4/OD!D4 -> 459.77011 | E4: =FL!E4/OD!E4 -> 431.81818 | F4: =FL!F4/OD!F4 -> 3270.5882 | G4: =FL!G4/OD!G4 -> 2586.2069 | H4: =FL!H4/OD!H4 -> 2800 | I4: =FL!I4/OD!I4 -> 2212.5 | J4: =FL!J4/OD!J4 -> 4231.7073 | ... N4: =FL!N4/OD!N4 -> 337.07865
A5: 0.027453704 | B5: 40 | C5: =FL!C5/OD!C5 -> 384.61538 | D5: =FL!D5/OD!D5 -> 393.25843 | E5: =FL!E5/OD!E5 -> 322.22222 | F5: =FL!F5/OD!F5 -> 3000 | G5: =FL!G5/OD!G5 -> 2784.0909 | H5: =FL!H5/OD!H5 -> 2906.9767 | I5: =FL!I5/OD!I5 -> 2375 | J5: =FL!J5/OD!J5 -> 4313.253 | ... N5: =FL!N5/OD!N5 -> 395.6044
A6: 0.034398148 | B6: 50 | C6: =FL!C6/OD!C6 -> 376.34409 | D6: =FL!D6/OD!D6 -> 489.13043 | E6: =FL!E6/OD!E6 -> 365.5914 | F6: =FL!F6/OD!F6 -> 3067.4157 | G6: =FL!G6/OD!G6 -> 2538.4615 | H6: =FL!H6/OD!H6 -> 3079.5455 | I6: =FL!I6/OD!I6 -> 2160.4938 | J6: =FL!J6/OD!J6 -> 4928.5714 | ... N6: =FL!N6/OD!N6 -> 329.78723
A7: 0.041342593 | B7: 60 | C7: =FL!C7/OD!C7 -> 350.51546 | D7: =FL!D7/OD!D7 -> 406.25 | E7: =FL!E7/OD!E7 -> 525.7732 | F7: =FL!F7/OD!F7 -> 3000 | G7: =FL!G7/OD!G7 -> 2787.234 | H7: =FL!H7/OD!H7 -> 2560.4396 | I7: =FL!I7/OD!I7 -> 2475.6098 | J7: =FL!J7/OD!J7 -> 5023.2558 | ... N7: =FL!N7/OD!N7 -> 357.14286
A8: 0.048287037 | B8: 70 | C8: =FL!C8/OD!C8 -> 323.52941 | D8: =FL!D8/OD!D8 -> 376.23762 | E8: =FL!E8/OD!E8 -> 196.07843 | F8: =FL!F8/OD!F8 -> 3520.4082 | G8: =FL!G8/OD!G8 -> 3061.2245 | H8: =FL!H8/OD!H8 -> 3322.9167 | I8: =FL!I8/OD!I8 -> 2756.0976 | J8: =FL!J8/OD!J8 -> 5544.4444 | ... N8: =FL!N8/OD!N8 -> 362.7451
A9: 0.055231481 | B9: 80 | C9: =FL!C9/OD!C9 -> 348.62385 | D9: =FL!D9/OD!D9 -> 222.22222 | E9: =FL!E9/OD!E9 -> 381.81818 | F9: =FL!F9/OD!F9 -> 4174.7573 | G9: =FL!G9/OD!G9 -> 3368.932 | H9: =FL!H9/OD!H9 -> 3841.5842 | I9: =FL!I9/OD!I9 -> 2590.3614 | J9: =FL!J9/OD!J9 -> 5902.1739 | ... N9: =FL!N9/OD!N9 -> 348.62385
A10: 0.062175926 | B10: 90 | C10: =FL!C10/OD!C10 -> 260.86957 | D10: =FL!D10/OD!D10 -> 304.34783 | E10: =FL!E10/OD!E10 -> 208.69565 | F10: =FL!F10/OD!F10 -> 4403.6697 | G10: =FL!G10/OD!G10 -> 3918.1818 | H10: =FL!H10/OD!H10 -> 4219.0476 | I10: =FL!I10/OD!I10 -> 3352.9412 | J10: =FL!J10/OD!J10 -> 7000 | ... N10: =FL!N10/OD!N10 -> 408.69565
A11: 0.06912037 | B11: 100 | C11: =FL!C11/OD!C11 -> 298.3871 | D11: =FL!D11/OD!D11 -> 404.95868 | E11: =FL!E11/OD!E11 -> 346.77419 | F11: =FL!F11/OD!F11 -> 5250 | G11: =FL!G11/OD!G11 -> 4529.9145 | H11: =FL!H11/OD!H11 -> 4778.7611 | I11: =FL!I11/OD!I11 -> 3379.3103 | J11: =FL!J11/OD!J11 -> 7494.9495 | ... N11: =FL!N11/OD!N11 -> 256.19835
A12: 0.076064815 | B12: 110 | C12: =FL!C12/OD!C12 -> 263.15789 | D12: =FL!D12/OD!D12 -> 384.61538 | E12: =FL!E12/OD!E12 -> 280.30303 | F12: =FL!F12/OD!F12 -> 6214.876 | G12: =FL!G12/OD!G12 -> 5614.7541 | H12: =FL!H12/OD!H12 -> 5294.1176 | I12: =FL!I12/OD!I12 -> 3797.7528 | J12: =FL!J12/OD!J12 -> 9038.835 | ... N12: =FL!N12/OD!N12 -> 356.58915
A13: 0.083009259 | B13: 120 | C13: =FL!C13/OD!C13 -> 243.05556 | D13: =FL!D13/OD!D13 -> 288.73239 | E13: =FL!E13/OD!E13 -> 279.72028 | F13: =FL!F13/OD!F13 -> 6348.4848 | G13: =FL!G13/OD!G13 -> 5696.9697 | H13: =FL!H13/OD!H13 -> 6070.8661 | I13: =FL!I13/OD!I13 -> 4351.6484 | J13: =FL!J13/OD!J13 -> 10500 | ... N13: =FL!N13/OD!N13 -> 354.60993
... A110: 0.75662037 | B110: 1090 | C110: =FL!C110/OD!C110 -> 897.57914 | D110: =FL!D110/OD!D110 -> 883.63636 | E110: =FL!E110/OD!E110 -> 905.01792 | F110: =FL!F110/OD!F110 -> 2364.3411 | G110: =FL!G110/OD!G110 -> 2425.8189 | H110: =FL!H110/OD!H110 -> 2417.9688 | I110: =FL!I110/OD!I110 -> 98074.488 | J110: =FL!J110/OD!J110 -> 79546.789 | ... N110: =FL!N110/OD!N110 -> 893.00412
